2024-11-01 19:36:09,889 INFO    StreamThr :2993349 [internal.py:wandb_internal():85] W&B internal server running at pid: 2993349, started at: 2024-11-01 19:36:09.887777
2024-11-01 19:36:09,892 DEBUG   HandlerThread:2993349 [handler.py:handle_request():158] handle_request: status
2024-11-01 19:36:09,897 INFO    WriterThread:2993349 [datastore.py:open_for_write():87] open: /home/geng/WARDEN/src/wandb/run-20241101_193609-j8rq3bv0/run-j8rq3bv0.wandb
2024-11-01 19:36:09,898 DEBUG   SenderThread:2993349 [sender.py:send():379] send: header
2024-11-01 19:36:09,988 DEBUG   SenderThread:2993349 [sender.py:send():379] send: run
2024-11-01 19:36:14,989 DEBUG   HandlerThread:2993349 [handler.py:handle_request():158] handle_request: keepalive
2024-11-01 19:36:19,990 DEBUG   HandlerThread:2993349 [handler.py:handle_request():158] handle_request: keepalive
2024-11-01 19:36:24,991 DEBUG   HandlerThread:2993349 [handler.py:handle_request():158] handle_request: keepalive
2024-11-01 19:36:29,992 DEBUG   HandlerThread:2993349 [handler.py:handle_request():158] handle_request: keepalive
2024-11-01 19:36:34,993 DEBUG   HandlerThread:2993349 [handler.py:handle_request():158] handle_request: keepalive
2024-11-01 19:36:39,994 DEBUG   HandlerThread:2993349 [handler.py:handle_request():158] handle_request: keepalive
2024-11-01 19:36:44,994 DEBUG   HandlerThread:2993349 [handler.py:handle_request():158] handle_request: keepalive
2024-11-01 19:36:49,995 DEBUG   HandlerThread:2993349 [handler.py:handle_request():158] handle_request: keepalive
2024-11-01 19:36:54,996 DEBUG   HandlerThread:2993349 [handler.py:handle_request():158] handle_request: keepalive
2024-11-01 19:36:59,997 DEBUG   HandlerThread:2993349 [handler.py:handle_request():158] handle_request: keepalive
2024-11-01 19:37:04,998 DEBUG   HandlerThread:2993349 [handler.py:handle_request():158] handle_request: keepalive
2024-11-01 19:37:09,999 DEBUG   HandlerThread:2993349 [handler.py:handle_request():158] handle_request: keepalive
2024-11-01 19:37:14,163 INFO    SenderThread:2993349 [retry.py:__call__():172] Retry attempt failed:
Traceback (most recent call last):
  File "/home/geng/miniconda3/envs/EmbMarker/lib/python3.8/site-packages/urllib3/connection.py", line 196, in _new_conn
    sock = connection.create_connection(
  File "/home/geng/miniconda3/envs/EmbMarker/lib/python3.8/site-packages/urllib3/util/connection.py", line 85, in create_connection
    raise err
  File "/home/geng/miniconda3/envs/EmbMarker/lib/python3.8/site-packages/urllib3/util/connection.py", line 73, in create_connection
    sock.connect(sa)
socket.timeout: timed out

The above exception was the direct cause of the following exception:

Traceback (most recent call last):
  File "/home/geng/miniconda3/envs/EmbMarker/lib/python3.8/site-packages/urllib3/connectionpool.py", line 789, in urlopen
    response = self._make_request(
  File "/home/geng/miniconda3/envs/EmbMarker/lib/python3.8/site-packages/urllib3/connectionpool.py", line 490, in _make_request
    raise new_e
  File "/home/geng/miniconda3/envs/EmbMarker/lib/python3.8/site-packages/urllib3/connectionpool.py", line 466, in _make_request
    self._validate_conn(conn)
  File "/home/geng/miniconda3/envs/EmbMarker/lib/python3.8/site-packages/urllib3/connectionpool.py", line 1095, in _validate_conn
    conn.connect()
  File "/home/geng/miniconda3/envs/EmbMarker/lib/python3.8/site-packages/urllib3/connection.py", line 615, in connect
    self.sock = sock = self._new_conn()
  File "/home/geng/miniconda3/envs/EmbMarker/lib/python3.8/site-packages/urllib3/connection.py", line 205, in _new_conn
    raise ConnectTimeoutError(
urllib3.exceptions.ConnectTimeoutError: (<urllib3.connection.HTTPSConnection object at 0x7f7554eec1f0>, 'Connection to api.wandb.ai timed out. (connect timeout=20)')

The above exception was the direct cause of the following exception:

Traceback (most recent call last):
  File "/home/geng/miniconda3/envs/EmbMarker/lib/python3.8/site-packages/requests/adapters.py", line 667, in send
    resp = conn.urlopen(
  File "/home/geng/miniconda3/envs/EmbMarker/lib/python3.8/site-packages/urllib3/connectionpool.py", line 843, in urlopen
    retries = retries.increment(
  File "/home/geng/miniconda3/envs/EmbMarker/lib/python3.8/site-packages/urllib3/util/retry.py", line 519, in increment
    raise MaxRetryError(_pool, url, reason) from reason  # type: ignore[arg-type]
urllib3.exceptions.MaxRetryError: HTTPSConnectionPool(host='api.wandb.ai', port=443): Max retries exceeded with url: /graphql (Caused by ConnectTimeoutError(<urllib3.connection.HTTPSConnection object at 0x7f7554eec1f0>, 'Connection to api.wandb.ai timed out. (connect timeout=20)'))

During handling of the above exception, another exception occurred:

Traceback (most recent call last):
  File "/home/geng/miniconda3/envs/EmbMarker/lib/python3.8/site-packages/wandb/sdk/lib/retry.py", line 131, in __call__
    result = self._call_fn(*args, **kwargs)
  File "/home/geng/miniconda3/envs/EmbMarker/lib/python3.8/site-packages/wandb/sdk/internal/internal_api.py", line 345, in execute
    return self.client.execute(*args, **kwargs)  # type: ignore
  File "/home/geng/miniconda3/envs/EmbMarker/lib/python3.8/site-packages/wandb/vendor/gql-0.2.0/wandb_gql/client.py", line 52, in execute
    result = self._get_result(document, *args, **kwargs)
  File "/home/geng/miniconda3/envs/EmbMarker/lib/python3.8/site-packages/wandb/vendor/gql-0.2.0/wandb_gql/client.py", line 60, in _get_result
    return self.transport.execute(document, *args, **kwargs)
  File "/home/geng/miniconda3/envs/EmbMarker/lib/python3.8/site-packages/wandb/sdk/lib/gql_request.py", line 58, in execute
    request = self.session.post(self.url, **post_args)
  File "/home/geng/miniconda3/envs/EmbMarker/lib/python3.8/site-packages/requests/sessions.py", line 637, in post
    return self.request("POST", url, data=data, json=json, **kwargs)
  File "/home/geng/miniconda3/envs/EmbMarker/lib/python3.8/site-packages/requests/sessions.py", line 589, in request
    resp = self.send(prep, **send_kwargs)
  File "/home/geng/miniconda3/envs/EmbMarker/lib/python3.8/site-packages/requests/sessions.py", line 703, in send
    r = adapter.send(request, **kwargs)
  File "/home/geng/miniconda3/envs/EmbMarker/lib/python3.8/site-packages/requests/adapters.py", line 688, in send
    raise ConnectTimeout(e, request=request)
requests.exceptions.ConnectTimeout: HTTPSConnectionPool(host='api.wandb.ai', port=443): Max retries exceeded with url: /graphql (Caused by ConnectTimeoutError(<urllib3.connection.HTTPSConnection object at 0x7f7554eec1f0>, 'Connection to api.wandb.ai timed out. (connect timeout=20)'))
2024-11-01 19:37:15,000 DEBUG   HandlerThread:2993349 [handler.py:handle_request():158] handle_request: keepalive
2024-11-01 19:37:20,000 DEBUG   HandlerThread:2993349 [handler.py:handle_request():158] handle_request: keepalive
2024-11-01 19:37:25,001 DEBUG   HandlerThread:2993349 [handler.py:handle_request():158] handle_request: keepalive
2024-11-01 19:37:30,002 DEBUG   HandlerThread:2993349 [handler.py:handle_request():158] handle_request: keepalive
2024-11-01 19:37:35,003 DEBUG   HandlerThread:2993349 [handler.py:handle_request():158] handle_request: keepalive
2024-11-01 19:37:40,004 DEBUG   HandlerThread:2993349 [handler.py:handle_request():158] handle_request: cancel
2024-11-01 19:37:40,004 DEBUG   HandlerThread:2993349 [handler.py:handle_request():158] handle_request: cancel
2024-11-01 19:37:40,004 DEBUG   SenderThread:2993349 [sender.py:send():388] Record cancelled: run
2024-11-01 19:37:40,005 DEBUG   HandlerThread:2993349 [handler.py:handle_request():158] handle_request: status_report
2024-11-01 19:37:42,017 DEBUG   HandlerThread:2993349 [handler.py:handle_request():158] handle_request: shutdown
2024-11-01 19:37:42,017 INFO    HandlerThread:2993349 [handler.py:finish():882] shutting down handler
2024-11-01 19:37:43,005 INFO    SenderThread:2993349 [sender.py:finish():1608] shutting down sender
2024-11-01 19:37:43,006 INFO    WriterThread:2993349 [datastore.py:close():296] close: /home/geng/WARDEN/src/wandb/run-20241101_193609-j8rq3bv0/run-j8rq3bv0.wandb
